Workbook

Sheet RESUMEN PROYECTO
C5: UNIDAD FUNCIONAL / INSTALACIÓN | D5: COSTO DIRECTO | E5: ADMINISTRACIÓN - 22% - | F5: IMPREVISTOS - 4% - | G5: UTILIDAD - 4% - | H5: I.V.A. - 19% - (sobre utilidad) | I5: COSTO TOTAL
C7: UF 0D | D7: =ROUND(UUFF!E17,2) -> 1.6466883e+10 | E7: =ROUND((D7*22%),2) -> 3.6227143e+09 | F7: =ROUND((D7*4%),2) -> 6.5867533e+08 | G7: =ROUND((D7*4%),2) -> 6.5867533e+08 | H7: =ROUND((G7*19%),2) -> 1.2514831e+08 | I7: =SUM(D7:H7) -> 2.1532096e+10
C8: UF 1 | D8: =ROUND(UUFF!G17,2) -> 6.2530024e+08 | E8: =ROUND((D8*22%),2) -> 1.3756605e+08 | F8: =ROUND((D8*4%),2) -> 25012010 | G8: =ROUND((D8*4%),2) -> 25012010 | H8: =ROUND((G8*19%),2) -> 4752281.8 | I8: =SUM(D8:H8) -> 8.176426e+08
C9: UF 2 | D9: =ROUND(UUFF!I17,2) -> 2.233377e+09 | E9: =ROUND((D9*22%),2) -> 4.9134294e+08 | F9: =ROUND((D9*4%),2) -> 89335080 | G9: =ROUND((D9*4%),2) -> 89335080 | H9: =ROUND((G9*19%),2) -> 16973665 | I9: =SUM(D9:H9) -> 2.9203638e+09
C10: UF 3 | D10: =ROUND(UUFF!K17,2) -> 1.396382e+09 | E10: =ROUND((D10*22%),2) -> 3.0720404e+08 | F10: =ROUND((D10*4%),2) -> 55855280 | G10: =ROUND((D10*4%),2) -> 55855280 | H10: =ROUND((G10*19%),2) -> 10612503 | I10: =SUM(D10:H10) -> 1.8259091e+09
C11: UF 4 | D11: =ROUND(UUFF!M17,2) -> 1.2374223e+09 | E11: =ROUND((D11*22%),2) -> 2.722329e+08 | F11: =ROUND((D11*4%),2) -> 49496892 | G11: =ROUND((D11*4%),2) -> 49496892 | H11: =ROUND((G11*19%),2) -> 9404409.4 | I11: =SUM(D11:H11) -> 1.6180534e+09
C12: UF 5 | D12: =ROUND(UUFF!O17,2) -> 5.1123698e+09 | E12: =ROUND((D12*22%),2) -> 1.1247214e+09 | F12: =ROUND((D12*4%),2) -> 2.0449479e+08 | G12: =ROUND((D12*4%),2) -> 2.0449479e+08 | H12: =ROUND((G12*19%),2) -> 38854011 | I12: =SUM(D12:H12) -> 6.6849348e+09
C13: UF 6 | D13: =ROUND(UUFF!R17,2) -> 1.1657859e+09 | E13: =ROUND((D13*22%),2) -> 2.564729e+08 | F13: =ROUND((D13*4%),2) -> 46631436 | G13: =ROUND((D13*4%),2) -> 46631436 | H13: =ROUND((G13*19%),2) -> 8859972.8 | I13: =SUM(D13:H13) -> 1.5243816e+09
C14: UF 7 | D14: =ROUND(UUFF!T17,2) -> 1.5519735e+09 | E14: =ROUND((D14*22%),2) -> 3.4143416e+08 | F14: =ROUND((D14*4%),2) -> 62078938 | G14: =ROUND((D14*4%),2) -> 62078938 | H14: =ROUND((G14*19%),2) -> 11794998 | I14: =SUM(D14:H14) -> 2.0293605e+09
C15: UF 8 | D15: =ROUND(UUFF!V17,2) -> 1.0944928e+09 | E15: =ROUND((D15*22%),2) -> 2.4078842e+08 | F15: =ROUND((D15*4%),2) -> 43779713 | G15: =ROUND((D15*4%),2) -> 43779713 | H15: =ROUND((G15*19%),2) -> 8318145.4 | I15: =SUM(D15:H15) -> 1.4311588e+09
C16: UF 9 | D16: =ROUND(UUFF!X17,2) -> 1.0151298e+09 | E16: =ROUND((D16*22%),2) -> 2.2332856e+08 | F16: =ROUND((D16*4%),2) -> 40605192 | G16: =ROUND((D16*4%),2) -> 40605192 | H16: =ROUND((G16*19%),2) -> 7714986.5 | I16: =SUM(D16:H16) -> 1.3273837e+09
C17: UF 10 | D17: =ROUND(UUFF!Z17,2) -> 1.1911112e+09 | E17: =ROUND((D17*22%),2) -> 2.6204447e+08 | F17: =ROUND((D17*4%),2) -> 47644449 | G17: =ROUND((D17*4%),2) -> 47644449 | H17: =ROUND((G17*19%),2) -> 9052445.4 | I17: =SUM(D17:H17) -> 1.5574971e+09
C18: UF 11 | D18: =ROUND(UUFF!AB17,2) -> 4.0077251e+09 | E18: =ROUND((D18*22%),2) -> 8.8169953e+08 | F18: =ROUND((D18*4%),2) -> 1.60309e+08 | G18: =ROUND((D18*4%),2) -> 1.60309e+08 | H18: =ROUND((G18*19%),2) -> 30458711 | I18: =SUM(D18:H18) -> 5.2405014e+09
C19: UF 12 | D19: =ROUND(UUFF!AD17,2) -> 2.1686404e+09 | E19: =ROUND((D19*22%),2) -> 4.7710089e+08 | F19: =ROUND((D19*4%),2) -> 86745617 | G19: =ROUND((D19*4%),2) -> 86745617 | H19: =ROUND((G19*19%),2) -> 16481667 | I19: =SUM(D19:H19) -> 2.8357142e+09
C20: UF 13 | D20: =ROUND(UUFF!AF17,2) -> 1.2633158e+09 | E20: =ROUND((D20*22%),2) -> 2.7792947e+08 | F20: =ROUND((D20*4%),2) -> 50532631 | G20: =ROUND((D20*4%),2) -> 50532631 | H20: =ROUND((G20*19%),2) -> 9601199.9 | I20: =SUM(D20:H20) -> 1.6519117e+09
C21: PEAJES | D21: =ROUND((UUFF!AI11+UUFF!AI12),2) -> 3.4309473e+09 | E21: =ROUND((D21*22%),2) -> 7.5480841e+08 | F21: =ROUND((D21*4%),2) -> 1.3723789e+08 | G21: =ROUND((D21*4%),2) -> 1.3723789e+08 | H21: =ROUND((G21*19%),2) -> 26075200 | I21: =SUM(D21:H21) -> 4.4863067e+09
C22: PESAJES | D22: =ROUND(UUFF!AI13,2) -> 3.2916973e+09 | E22: =ROUND((D22*22%),2) -> 7.2417341e+08 | F22: =ROUND((D22*4%),2) -> 1.3166789e+08 | G22: =ROUND((D22*4%),2) -> 1.3166789e+08 | H22: =ROUND((G22*19%),2) -> 25016900 | I22: =SUM(D22:H22) -> 4.3042234e+09
C23: CCO | D23: =ROUND(UUFF!AI15,2) -> 3.934077e+09 | E23: =ROUND((D23*22%),2) -> 8.6549694e+08 | F23: =ROUND((D23*4%),2) -> 1.5736308e+08 | G23: =ROUND((D23*4%),2) -> 1.5736308e+08 | H23: =ROUND((G23*19%),2) -> 29898985 | I23: =SUM(D23:H23) -> 5.1441991e+09
C24: RADIO COMUNICACIONES | D24: =ROUND(UUFF!AI14,2) -> 1.8120381e+09 | E24: =ROUND((D24*22%),2) -> 3.9864838e+08 | F24: =ROUND((D24*4%),2) -> 72481524 | G24: =ROUND((D24*4%),2) -> 72481524 | H24: =ROUND((G24*19%),2) -> 13771490 | I24: =SUM(D24:H24) -> 2.369421e+09
C26: TOTALES | D26: =SUM(D7:D24) -> 5.2998669e+10 | E26: =SUM(E7:E24) -> 1.1659707e+10 | F26: =SUM(F7:F24) -> 2.1199468e+09 | G26: =SUM(G7:G24) -> 2.1199468e+09 | H26: =SUM(H7:H24) -> 4.0278988e+08 | I26: =SUM(D26:H26) -> 6.9301059e+10

Sheet RESUMEN COMPONENTES
B2: PROYECTO TRONCAL MAGDALENA 1
B3: TABLA DE CANTIDADES
B4: UNIDADES FUNCIONALES TOTAL 0 - 13
C6: PRESUPUESTO WUXY
B8: ítem | C8: ITS | E8: COSTO TOTAL
B10: 1 | C10: SISTEMA DE TELEFONÍA DE EMERGENCIA | E10: ='Postes SOS'!J40 -> 6.7891053e+09
B11: 2 | C11: ESTACIÓN METEOROLÓGICA | E11: ='ESTACIÓN METEOROLOGICA'!J40 -> 4.8677534e+08
B12: 3 | C12: PANEL DE MENSAJERÍA VARIABLE | E12: =PMV!J35 -> 1.0900278e+10
B13: 4 | C13: SISTEMA DE CONTROL DE ALTURA | E13: =GALIBO!J43 -> 2.419255e+09
B14: 5 | C14: ESTACIÓN TOMA DE DATOS | E14: =ETD!J35 -> 1.7151537e+09
B15: 6 | C15: SISTEMA DE CCTV | E15: =CCTV!J36 -> 1.8944836e+09
B16: 7 | C16: FIBRA OPTICA Y COMUNICACIONES | E16: ='FO COMUNICACION'!J33 -> 1.6324858e+10
B17: 8 | C17: PEAJE | E17: =PEAJE!J93 -> 3.3525228e+09
B18: 9 | C18: PESAJE (Básculas sentido Sur y Norte) | E18: ='BásculaS Sur y Norte'!J81 -> 3.2916973e+09
B19: 10 | C19: RADIO COMUNICACIONES | E19: ='RADIO COMUNICACIONES'!J66 -> 1.8120381e+09
B20: 11 | C20: CCO | E20: =CCO!J59 -> 3.934077e+09
B21: 12 | C21: CONTROL DE ACCESOS EN PEAJE | E21: ='Control de accesos en Peaje'!J27 -> 78424521
B23: TOTAL COSTOS DIRECTOS | E23: =SUM(E10:E21) -> 5.2998669e+10
B24: ADMINISTRACION (A) | D24: 0.22 | E24: =E23*D24 -> 1.1659707e+10
B25: IMPREVISTOS (I) | D25: 0.04 | E25: =E23*D25 -> 2.1199468e+09
B26: UTILIDAD (U) | D26: 0.04 | E26: =E23*D26 -> 2.1199468e+09
B27: SUBTOTAL COSTOS DIRECTOS + AIU | E27: =SUM(E23:E26) -> 6.8898269e+10
B28: IVA SOBRE LA UTILIDAD 19% | D28: 0.19 | E28: =E26*D28 -> 4.0278988e+08
B30: TOTAL COSTO DIRECTO+AIU + IVA | E30: =E27+E28 -> 6.9301059e+10
B33: ítem | C33: ITS | E33: COSTO TOTAL
B35: 13 | C35: PASO ELEVADO FIBRA OPTICA | E35: ='Paso elevado FO'!J17 -> 82081639
B37: TOTAL COSTOS DIRECTOS | E37: =E35 -> 82081639
B38: ADMINISTRACION (A) | D38: 0.22 | E38: =E37*D38 -> 18057961
B39: IMPREVISTOS (I) | D39: 0.04 | E39: =E37*D39 -> 3283265.6
B40: UTILIDAD (U) | D40: 0.04 | E40: =E37*D40 -> 3283265.6
B41: SUBTOTAL COSTOS DIRECTOS + AIU | E41: =SUM(E37:E40) -> 1.0670613e+08
B42: IVA SOBRE LA UTILIDAD 19% | D42: 0.19 | E42: =E40*D42 -> 623820.46
B44: TOTAL COSTO DIRECTO+AIU + IVA | E44: =E41+E42 -> 1.0732995e+08
B46: ítem | C46: ITS | E46: COSTO TOTAL
B48: 14 | C48: BÁSCULAS DINAMICAS EN ZONA DE PEAJE | E48: ='Basculas Dinamicas en peaje'!J31 -> 3182719610
B50: TOTAL COSTOS DIRECTOS | E50: =E48 -> 3182719610
B51: ADMINISTRACION (A) | D51: 0.22 | E51: =E50*D51 -> 7.0019831e+08
B52: IMPREVISTOS (I) | D52: 0.04 | E52: =E50*D52 -> 1.2730878e+08
B53: UTILIDAD (U) | D53: 0.04 | E53: =E50*D53 -> 1.2730878e+08
B54: SUBTOTAL COSTOS DIRECTOS + AIU | E54: =SUM(E50:E53) -> 4137535493
...

Sheet UBICACIÓN EQUIPOS ITS v3
A1: UBICACIÓN EQUIPOS ITS | M1: SISTEMA | N1: CANTIDAD
A2: 45918 | G2: SEPARACIÓN | J2: OBSERVACIÓN | N2: NO OBJETADOS | O2: EPC
A3: CANTIDAD | B3: RUTA | C3: UF | D3: VIA | E3: SISTEMA | F3: UBICACIÓN | G3: SOS | H3: PMV IZQ | I3: PMV DERE | M3: RADAR-ANPR | N3: 38 | O3: =COUNTIF(E4:E174,M3) -> 12
M4: PMV | N4: 29 | O4: =COUNTIF(E4:E175,M4) -> 28
A5: 1 | B5: 4510 | C5: 5.2 | D5: UNIDIRECCIONAL | E5: CCTV | F5: 38100 | M5: CCTV | N5: 121 | O5: =COUNTIF(E4:E176,M5) -> 30
A6: 2 | B6: 4510 | C6: 0D | D6: SEPARADOR | E6: CCTV | F6: 40050 | M6: POSTE SOS | N6: 88 | O6: =COUNTIF(E4:E177,M6) -> 88
A7: 3 | B7: 4510 | C7: 0D | D7: DERECHA | E7: PMV | F7: 41000 | J7: 40450 | K7: INTER KORAN | M7: GALIBO | N7: 19 | O7: =COUNTIF(E4:E178,M7) -> 8
A8: 4 | B8: 4510 | C8: 0D | D8: IZQUERDA | E8: PMV | F8: 41200 | M8: METEO | N8: 11 | O8: =COUNTIF(E4:E179,M8) -> 4
A9: 5 | B9: 4510 | C9: 0D | D9: DERECHA | E9: POSTE SOS | F9: 41180 | M9: TOTAL | N9: =SUM(N3:N8) -> 306 | O9: =SUM(O3:O8) -> 170
A10: 6 | B10: 4510 | C10: 0D | D10: DERECHA | E10: GALIBO | F10: 41350
A11: 7 | B11: 4510 | C11: 0D | D11: IZQUERDA | E11: POSTE SOS | F11: 43560 | G11: =F11-F9 -> 2380
A12: 8 | B12: 4510 | C12: 0D | D12: DERECHA | E12: POSTE SOS | F12: 46550 | G12: =F12-F11 -> 2990 | J12: 48360 | K12: PEATONAL
A13: 9 | B13: 4510 | C13: 0D | D13: IZQUERDA | E13: POSTE SOS | F13: 49550 | G13: =F13-F12 -> 3000
A14: 10 | B14: 4510 | C14: 0D | D14: DERECHA | E14: POSTE SOS | F14: 52550 | G14: =F14-F13 -> 3000
A15: 11 | B15: 4510 | C15: 0D | D15: IZQUERDA | E15: RADAR-ANPR | F15: 54000
A16: 12 | B16: 4510 | C16: 0D | D16: DERECHA | E16: RADAR-ANPR | F16: 54000
A17: 13 | B17: 4510 | C17: 0D | D17: IZQUERDA | E17: POSTE SOS | F17: 55500 | G17: =F17-F14 -> 2950
A18: 14 | B18: 4510 | C18: 0D | D18: IZQUERDA | E18: PMV | F18: 57350 | H18: =F18-F8 -> 16150
A19: 15 | B19: 4510 | C19: 0D | D19: DERECHA | E19: POSTE SOS | F19: 58500 | G19: =F19-F17 -> 3000
A20: 16 | B20: 4510 | C20: 0D | D20: DERECHA | E20: PMV | F20: 58950 | I20: =F20-F7 -> 17950
A21: 17 | B21: 4510 | C21: 0D | D21: IZQUERDA | E21: POSTE SOS | F21: 61500 | G21: =F21-F19 -> 3000
A22: 18 | B22: 4510 | C22: 0D | D22: DERECHA | E22: POSTE SOS | F22: 64450 | G22: =F22-F21 -> 2950
A23: 19 | B23: 4510 | C23: 0D | D23: IZQUERDA | E23: POSTE SOS | F23: 67150 | G23: =F23-F22 -> 2700
A24: 20 | B24: 4510 | C24: 0D | D24: SEPARADOR | E24: CCTV | F24: 69000 | J24: 68434 | K24: PEATONAL
A25: 21 | B25: 4510 | C25: 0D | D25: DERECHA | E25: POSTE SOS | F25: 70150 | G25: =F25-F23 -> 3000
A26: 22 | B26: 4510 | C26: 0D | D26: IZQUERDA | E26: POSTE SOS | F26: 73110 | G26: =F26-F25 -> 2960
A27: 23 | B27: 4510 | C27: 0D | D27: DERECHA | E27: POSTE SOS | F27: 76020 | G27: =F27-F26 -> 2910
A28: 24 | B28: 4510 | C28: 0D | D28: IZQUERDA | E28: PMV | F28: 77350 | H28: =F28-F18 -> 20000
A29: 25 | B29: 4510 | C29: 0D | D29: IZQUERDA | E29: POSTE SOS | F29: 78800 | G29: =F29-F27 -> 2780
A30: 26 | B30: 4510 | C30: 0D | D30: DERECHA | E30: PMV | F30: 78950 | I30: =F30-F20 -> 20000
A31: 27 | B31: 4510 | C31: 0D | D31: SEPARADOR | E31: CCTV | F31: 81000
A32: 28 | B32: 4510 | C32: 0D | D32: DERECHA | E32: POSTE SOS | F32: 81500 | G32: =F32-F29 -> 2700
A33: 29 | B33: 4510 | C33: 0D | D33: SEPARADOR | E33: METEO | F33: 83250
A34: 30 | B34: 4510 | C34: 0D | D34: IZQUERDA | E34: POSTE SOS | F34: 83950 | G34: =F34-F32 -> 2450
A35: 31 | B35: 4510 | C35: 1 | D35: SEPARADOR | E35: CCTV | F35: 85370
A36: 32 | B36: 4510 | C36: 1 | D36: DERECHA | E36: POSTE SOS | F36: 86900 | G36: =F36-F34 -> 2950 | J36: 86290 | K36: PEATONAL
A37: 33 | B37: 4510 | C37: 1 | D37: SEPARADOR | E37: CCTV | F37: 87100
A38: 34 | B38: 4510 | C38: 0D | D38: IZQUERDA | E38: POSTE SOS | F38: 89780 | G38: =F38-F36 -> 2880
A39: 35 | B39: 4510 | C39: 5.1 | D39: SEPARADOR | E39: CCTV | F39: 91850
A40: 36 | B40: 4510 | C40: 1 | D40: DERECHA | E40: POSTE SOS | F40: 92520 | G40: =F40-F38 -> 2740
...

Sheet UUFF
A2: SUB SISTEMA | B2: UNIDAD | D2: 0D | F2: 1 | H2: 2 | J2: 3 | L2: 4 | N2: 5 | Q2: 6 | S2: 7 | U2: 8 | W2: 9 | Y2: 10 | AA2: 11 | AC2: 12 | AE2: 13 | AH2: CANTIDAD TOTAL | AI2: COSTO DIRECTO
D3: CANT | E3: VALOR | F3: CANT | G3: VALOR | H3: CANT | I3: VALOR | J3: CANT | K3: VALOR | L3: CANT | M3: VALOR | N3: CANT | O3: VALOR | P3: WUXY | Q3: CANT | R3: VALOR | S3: CANT | T3: VALOR | U3: CANT | V3: VALOR | W3: CANT | X3: VALOR | Y3: CANT | Z3: VALOR | AA3: CANT | AB3: VALOR | AC3: CANT | AD3: VALOR | AE3: CANT | AF3: VALOR | AG3: WUXY | AK3: VALOR UNITARIO
A4: SOS | B4: UND | D4: 38 | E4: =D4*AK4 -> 2.9316591e+09 | F4: 2 | G4: =F4*AK4 -> 1.5429785e+08 | H4: 6 | I4: =H4*AK4 -> 4.6289354e+08 | J4: 3 | K4: =J4*AK4 -> 2.3144677e+08 | L4: 1 | M4: =L4*AK4 -> 77148923 | N4: 9 | O4: =N4*AK4 -> 6.9434031e+08 | P4: =D4+F4+H4+J4+L4+N4 -> 59 | Q4: 1 | R4: =Q4*AK4 -> 77148923 | S4: 2 | T4: =S4*AK4 -> 1.5429785e+08 | U4: 1 | V4: =U4*AK4 -> 77148923 | W4: 2 | X4: =W4*AK4 -> 1.5429785e+08 | Y4: 2 | Z4: =Y4*AK4 -> 1.5429785e+08 | AA4: 15 | AB4: =AA4*AK4 -> 1.1572339e+09 | AC4: 4 | AD4: =AC4*AK4 -> 3.0859569e+08 | AE4: 2 | AF4: =AE4*AK4 -> 1.5429785e+08 | AG4: =Q4+S4+U4+W4+Y4+AA4+AC4+AE4 -> 29 | AH4: =AG4+P4 -> 88 | AI4: =ROUND(AH4*AK4,2) -> 6.7891053e+09 | AK4: =ROUND('RESUMEN COMPONENTES'!E10/88,2) -> 77148923
A5: ESTACIÓN METEOROLÓGICA | B5: UND | D5: 1 | E5: =D5*AK5 -> 1.2169384e+08 | F5: 0 | G5: =F5*AK5 -> 0 | H5: 0 | I5: =H5*AK5 -> 0 | J5: 0 | K5: =J5*AK5 -> 0 | L5: 0 | M5: =L5*AK5 -> 0 | N5: 1 | O5: =N5*AK5 -> 1.2169384e+08 | P5: =D5+F5+H5+J5+L5+N5 -> 2 | Q5: 1 | R5: =Q5*AK5 -> 1.2169384e+08 | S5: 0 | T5: =S5*AK5 -> 0 | U5: 0 | V5: =U5*AK5 -> 0 | W5: 0 | X5: =W5*AK5 -> 0 | Y5: 0 | Z5: =Y5*AK5 -> 0 | AA5: 0 | AB5: =AA5*AK5 -> 0 | AC5: 0 | AD5: =AC5*AK5 -> 0 | AE5: 1 | AF5: =AE5*AK5 -> 1.2169384e+08 | AG5: =Q5+S5+U5+W5+Y5+AA5+AC5+AE5 -> 2 | AH5: =AG5+P5 -> 4 | AI5: =ROUND(AH5*AK5,2) -> 4.8677534e+08 | AK5: =ROUND('RESUMEN COMPONENTES'!E11/4,2) -> 1.2169384e+08
A6: PANEL DE MENSAJERÍA VARIABLE | B6: UND | D6: 13 | E6: =D6*AK6 -> 5.0608433e+09 | F6: 0 | G6: =F6*AK6 -> 0 | H6: 1 | I6: =H6*AK6 -> 3.8929564e+08 | J6: 1 | K6: =J6*AK6 -> 3.8929564e+08 | L6: 1 | M6: =L6*AK6 -> 3.8929564e+08 | N6: 3 | O6: =N6*AK6 -> 1.1678869e+09 | P6: =D6+F6+H6+J6+L6+N6 -> 19 | Q6: 0 | R6: =Q6*AK6 -> 0 | S6: 1 | T6: =S6*AK6 -> 3.8929564e+08 | U6: 1 | V6: =U6*AK6 -> 3.8929564e+08 | W6: 0 | X6: =W6*AK6 -> 0 | Y6: 1 | Z6: =Y6*AK6 -> 3.8929564e+08 | AA6: 5 | AB6: =AA6*AK6 -> 1.9464782e+09 | AC6: 1 | AD6: =AC6*AK6 -> 3.8929564e+08 | AE6: 0 | AF6: =AE6*AK6 -> 0 | AG6: =Q6+S6+U6+W6+Y6+AA6+AC6+AE6 -> 9 | AH6: =AG6+P6 -> 28 | AI6: =ROUND(AH6*AK6,2) -> 1.0900278e+10 | AK6: =ROUND('RESUMEN COMPONENTES'!E12/28,2) -> 3.8929564e+08
A7: GÁLIBO | B7: UND | D7: 3 | E7: =D7*AK7 -> 9.0722061e+08 | F7: 0 | G7: =F7*AK7 -> 0 | H7: 0 | I7: =H7*AK7 -> 0 | J7: 0 | K7: =J7*AK7 -> 0 | L7: 0 | M7: =L7*AK7 -> 0 | N7: 2 | O7: =N7*AK7 -> 6.0481374e+08 | P7: =D7+F7+H7+J7+L7+N7 -> 5 | Q7: 1 | R7: =Q7*AK7 -> 3.0240687e+08 | S7: 0 | T7: =S7*AK7 -> 0 | U7: 0 | V7: =U7*AK7 -> 0 | W7: 0 | X7: =W7*AK7 -> 0 | Y7: 0 | Z7: =Y7*AK7 -> 0 | AA7: 1 | AB7: =AA7*AK7 -> 3.0240687e+08 | AC7: 0 | AD7: =AC7*AK7 -> 0 | AE7: 1 | AF7: =AE7*AK7 -> 3.0240687e+08 | AG7: =Q7+S7+U7+W7+Y7+AA7+AC7+AE7 -> 3 | AH7: =AG7+P7 -> 8 | AI7: =ROUND(AH7*AK7,2) -> 2.419255e+09 | AK7: =ROUND('RESUMEN COMPONENTES'!E13/8,2) -> 3.0240687e+08
A8: ESTACIÓN TOMA DE DATOS + CAMARA PLACAS | B8: UND | D8: 5 | E8: =D8*AK8 -> 7.1464736e+08 | F8: 0 | G8: =F8*AK8 -> 0 | H8: 1 | I8: =H8*AK8 -> 1.4292947e+08 | J8: 0 | K8: =J8*AK8 -> 0 | L8: 1 | M8: =L8*AK8 -> 1.4292947e+08 | N8: 1 | O8: =N8*AK8 -> 1.4292947e+08 | P8: =D8+F8+H8+J8+L8+N8 -> 8 | Q8: 0 | R8: =Q8*AK8 -> 0 | S8: 1 | T8: =S8*AK8 -> 1.4292947e+08 | U8: 0 | V8: =U8*AK8 -> 0 | W8: 0 | X8: =W8*AK8 -> 0 | Y8: 0 | Z8: =Y8*AK8 -> 0 | AA8: 2 | AB8: =AA8*AK8 -> 2.8585894e+08 | AC8: 1 | AD8: =AC8*AK8 -> 1.4292947e+08 | AE8: 0 | AF8: =AE8*AK8 -> 0 | AG8: =Q8+S8+U8+W8+Y8+AA8+AC8+AE8 -> 4 | AH8: =AG8+P8 -> 12 | AI8: =ROUND(AH8*AK8,2) -> 1.7151537e+09 | AK8: =ROUND('RESUMEN COMPONENTES'!E14/12,2) -> 1.4292947e+08
A9: SISTEMA DE CCTV | B9: UND | D9: 7 | E9: =D9*AK9 -> 4.4204618e+08 | F9: 3 | G9: =F9*AK9 -> 1.8944836e+08 | H9: 2 | I9: =H9*AK9 -> 1.2629891e+08 | J9: 0 | K9: =J9*AK9 -> 0 | L9: 0 | M9: =L9*AK9 -> 0 | N9: 7 | O9: =N9*AK9 -> 4.4204618e+08 | P9: =D9+F9+H9+J9+L9+N9 -> 19 | Q9: 2 | R9: =Q9*AK9 -> 1.2629891e+08 | S9: 0 | T9: =S9*AK9 -> 0 | U9: 0 | V9: =U9*AK9 -> 0 | W9: 3 | X9: =W9*AK9 -> 1.8944836e+08 | Y9: 0 | Z9: =Y9*AK9 -> 0 | AA9: 5 | AB9: =AA9*AK9 -> 3.1574727e+08 | AC9: 0 | AD9: =AC9*AK9 -> 0 | AE9: 1 | AF9: =AE9*AK9 -> 63149454 | AG9: =Q9+S9+U9+W9+Y9+AA9+AC9+AE9 -> 11 | AH9: =AG9+P9 -> 30 | AI9: =ROUND(AH9*AK9,2) -> 1.8944836e+09 | AK9: =ROUND('RESUMEN COMPONENTES'!E15/30,2) -> 63149454
A10: FIBRA OPTICA Y COMUNICACIONES | B10: KM | D10: =(45.14+3.94+20+10.58+20+0.472)*1.12 -> 112.14784 | E10: =D10*AK10 -> 6.2887728e+09 | F10: =(1.64+2.843)*1.12 -> 5.02096 | G10: =F10*AK10 -> 2.8155403e+08 | H10: =(6.605+11.1)*1.12 -> 19.8296 | I10: =H10*AK10 -> 1.1119594e+09 | J10: =(0.56+8.74+3.05)*1.12 -> 13.832 | K10: =J10*AK10 -> 7.756396e+08 | L10: =10*1.12 -> 11.2 | M10: =L10*AK10 -> 6.2804826e+08 | N10: =(5.04+1.18+0.505+1.092+8.456+13.395+0.4+0.8)*1.12 -> 34.57216 | O10: =N10*AK10 -> 1.9386594e+09 | P10: =D10+F10+H10+J10+L10+N10 -> 196.60256 | Q10: =8.57*1.12 -> 9.5984 | R10: =Q10*AK10 -> 5.3823736e+08 | S10: =13.78*1.12 -> 15.4336 | T10: =S10*AK10 -> 8.654505e+08 | U10: =10*1.12 -> 11.2 | V10: =U10*AK10 -> 6.2804826e+08 | W10: =10.69*1.12 -> 11.9728 | X10: =W10*AK10 -> 6.7138359e+08 | Y10: =10.31*1.12 -> 11.5472 | Z10: =Y10*AK10 -> 6.4751775e+08 | AA10: 0 | AB10: =AA10*AK10 -> 0 | AC10: =21.142*1.12 -> 23.67904 | AD10: =AC10*AK10 -> 1.3278196e+09 | AE10: =9.9*1.12 -> 11.088 | AF10: =AE10*AK10 -> 6.2176777e+08 | AG10: =Q10+S10+U10+W10+Y10+AA10+AC10+AE10 -> 94.51904 | AH10: =AG10+P10 -> 291.1216 | AI10: =ROUND(AH10*AK10,2) -> 1.6324858e+10 | AK10: =ROUND('RESUMEN COMPONENTES'!E16/291.1216,2) -> 56075737
A11: PEAJE | B11: GLB | P11: 1 | AG11: 1 | AH11: =AG11+P11 -> 2 | AI11: =ROUND(AH11*AK11,2) -> 3.3525228e+09 | AK11: =ROUND('RESUMEN COMPONENTES'!E17/2,2) -> 1.6762614e+09
A12: CONTROL DE ACCESOS EN PEAJE | B12: GLB | AH12: 2 | AI12: =ROUND(AH12*AK12,2) -> 78424521 | AK12: =ROUND('RESUMEN COMPONENTES'!E21/2,2) -> 39212261
A13: PESAJE Básculas sentido Sur y Norte | B13: GLB | P13: 0 | AG13: 2 | AH13: =AG13+P13 -> 2 | AI13: =ROUND(AH13*AK13,2) -> 3.2916973e+09 | AK13: =ROUND('RESUMEN COMPONENTES'!E18/2,2) -> 1.6458487e+09
A14: RADIO COMUNICACIONES | B14: UND | D14: 3 | L14: 1 | P14: 3 | W14: 1 | AC14: 1 | AG14: 3 | AH14: =AG14+P14 -> 6 | AI14: =ROUND(AH14*AK14,2) -> 1.8120381e+09 | AK14: =ROUND('RESUMEN COMPONENTES'!E19/6,2) -> 3.0200635e+08
A15: CCO | B15: GLB | AH15: 1 | AI15: =ROUND(AH15*AK15,2) -> 3.934077e+09 | AK15: =ROUND('RESUMEN COMPONENTES'!E20,2) -> 3.934077e+09
A17: TOTAL COSTOS DIRECTOS | E17: =SUM(E4:E15) -> 1.6466883e+10 | G17: =SUM(G4:G15) -> 6.2530024e+08 | I17: =SUM(I4:I15) -> 2.233377e+09 | K17: =SUM(K4:K15) -> 1.396382e+09 | M17: =SUM(M4:M15) -> 1.2374223e+09 | O17: =SUM(O4:O15) -> 5.1123698e+09 | R17: =SUM(R4:R15) -> 1.1657859e+09 | T17: =SUM(T4:T15) -> 1.5519735e+09 | V17: =SUM(V4:V15) -> 1.0944928e+09 | X17: =SUM(X4:X15) -> 1.0151298e+09 | Z17: =SUM(Z4:Z15) -> 1.1911112e+09 | AB17: =SUM(AB4:AB15) -> 4.0077251e+09 | AD17: =SUM(AD4:AD15) -> 2.1686404e+09 | AF17: =SUM(AF4:AF15) -> 1.2633158e+09 | AI17: =SUM(AI4:AI15) -> 5.2998669e+10 | AK17: =SUM(E17:AF17) -> 4.0529909e+10
A18: ADMINISTRACIÓN | C18: 0.22 | E18: =E17*$C$18 -> 3.6227143e+09 | G18: =G17*$C$18 -> 1.3756605e+08 | I18: =I17*$C$18 -> 4.9134294e+08 | K18: =K17*$C$18 -> 3.0720404e+08 | M18: =M17*$C$18 -> 2.722329e+08 | O18: =O17*$C$18 -> 1.1247214e+09 | R18: =R17*$C$18 -> 2.564729e+08 | T18: =T17*$C$18 -> 3.4143416e+08 | V18: =V17*$C$18 -> 2.4078842e+08 | X18: =X17*$C$18 -> 2.2332856e+08 | Z18: =Z17*$C$18 -> 2.6204447e+08 | AB18: =AB17*$C$18 -> 8.8169953e+08 | AD18: =AD17*$C$18 -> 4.7710089e+08 | AF18: =AF17*$C$18 -> 2.7792947e+08 | AI18: =$AI$17*C18 -> 1.1659707e+10
A19: IMPREVISTOS | C19: 0.04 | E19: =E17*$C$19 -> 6.5867533e+08 | G19: =G17*$C$19 -> 25012010 | I19: =I17*$C$19 -> 89335080 | K19: =K17*$C$19 -> 55855280 | M19: =M17*$C$19 -> 49496892 | O19: =O17*$C$19 -> 2.0449479e+08 | R19: =R17*$C$19 -> 46631436 | T19: =T17*$C$19 -> 62078938 | V19: =V17*$C$19 -> 43779713 | X19: =X17*$C$19 -> 40605192 | Z19: =Z17*$C$19 -> 47644449 | AB19: =AB17*$C$19 -> 1.60309e+08 | AD19: =AD17*$C$19 -> 86745617 | AF19: =AF17*$C$19 -> 50532631 | AI19: =$AI$17*C19 -> 2.1199468e+09
A20: UTILIDAD | C20: 0.04 | E20: =E17*$C$20 -> 6.5867533e+08 | G20: =G17*$C$20 -> 25012010 | I20: =I17*$C$20 -> 89335080 | K20: =K17*$C$20 -> 55855280 | M20: =M17*$C$20 -> 49496892 | O20: =O17*$C$20 -> 2.0449479e+08 | R20: =R17*$C$20 -> 46631436 | T20: =T17*$C$20 -> 62078938 | V20: =V17*$C$20 -> 43779713 | X20: =X17*$C$20 -> 40605192 | Z20: =Z17*$C$20 -> 47644449 | AB20: =AB17*$C$20 -> 1.60309e+08 | AD20: =AD17*$C$20 -> 86745617 | AF20: =AF17*$C$20 -> 50532631 | AI20: =$AI$17*C20 -> 2.1199468e+09
A21: SUB TOTAL COSTOS DIRECTOS + AIU | E21: =E17+E18+E19+E20 -> 2.1406948e+10 | G21: =G17+G18+G19+G20 -> 8.1289032e+08 | I21: =I17+I18+I19+I20 -> 2.9033901e+09 | K21: =K17+K18+K19+K20 -> 1.8152966e+09 | M21: =M17+M18+M19+M20 -> 1.608649e+09 | O21: =O17+O18+O19+O20 -> 6.6460807e+09 | R21: =R17+R18+R19+R20 -> 1.5155217e+09 | T21: =T17+T18+T19+T20 -> 2.0175655e+09 | V21: =V17+V18+V19+V20 -> 1.4228407e+09 | X21: =X17+X18+X19+X20 -> 1.3196687e+09 | Z21: =Z17+Z18+Z19+Z20 -> 1.5484446e+09 | AB21: =AB17+AB18+AB19+AB20 -> 5.2100427e+09 | AD21: =AD17+AD18+AD19+AD20 -> 2.8192326e+09 | AF21: =AF17+AF18+AF19+AF20 -> 1.6423105e+09 | AI21: =SUM(AI17:AI20) -> 6.8898269e+10
A22: IVA SOBRE UTILIDAD | C22: 0.19 | E22: =E20*$C$22 -> 1.2514831e+08 | G22: =G20*$C$22 -> 4752281.8 | I22: =I20*$C$22 -> 16973665 | K22: =K20*$C$22 -> 10612503 | M22: =M20*$C$22 -> 9404409.4 | O22: =O20*$C$22 -> 38854011 | R22: =R20*$C$22 -> 8859972.8 | T22: =T20*$C$22 -> 11794998 | V22: =V20*$C$22 -> 8318145.4 | X22: =X20*$C$22 -> 7714986.4 | Z22: =Z20*$C$22 -> 9052445.4 | AB22: =AB20*$C$22 -> 30458711 | AD22: =AD20*$C$22 -> 16481667 | AF22: =AF20*$C$22 -> 9601199.9 | AI22: =C22*AI20 -> 4.0278988e+08
A24: COSTO TOTAL | E24: =E22+E21 -> 2.1532096e+10 | G24: =G22+G21 -> 8.176426e+08 | I24: =I22+I21 -> 2.9203638e+09 | K24: =K22+K21 -> 1.8259091e+09 | M24: =M22+M21 -> 1.6180534e+09 | O24: =O22+O21 -> 6.6849348e+09 | R24: =R22+R21 -> 1.5243816e+09 | T24: =T22+T21 -> 2.0293605e+09 | V24: =V22+V21 -> 1.4311588e+09 | X24: =X22+X21 -> 1.3273837e+09 | Z24: =Z22+Z21 -> 1.5574971e+09 | AB24: =AB22+AB21 -> 5.2405014e+09 | AD24: =AD22+AD21 -> 2.8357142e+09 | AF24: =AF22+AF21 -> 1.6519117e+09 | AI24: =AI22+AI21 -> 6.9301059e+10 | AK24: =AI4+AI5+AI6+AI7+AI8+AI9+AI10 -> 4.0529909e+10
AK25: =SUM(E17:AF17) -> 4.0529909e+10

Sheet Postes SOS
B2: PROYECTO TRONCAL MAGDALENA 1
B3: TABLA DE CANTIDADES | D3: PRESUPUESTO WUXY
B4: UNIDADES FUNCIONALES TOTAL 0 - 13
B8: ítem | C8: ITS | D8: Unidad | E8: Cantidad | F8: SUMINISTRO | H8: INSTALACIÓN PUESTA EN FUNCIONAMIENTO Y PRUEBAS | J8: COSTO TOTAL
B9: 1 | C9: SISTEMA DE TELEFONÍA DE EMERGENCIA | F9: Costo unitario | G9: Total suministro | H9: Costo unitario | I9: Total Instalación | J9: TOTAL
E10: TOTAL | F10: Col $ | G10: Col $ | H10: Col $ | I10: Col $ | J10: Col $
B11: =B9+0.01 -> 1.01 | C11: Teléfono SOS, con gabinete IP65 sin ingreso de agua. Incluye switch de puerta abierta. | D11: Un | E11: 88 | F11: 2504818.8 | G11: =E11*F11 -> 2.2042406e+08 | H11: 5783685.6 | I11: =E11*H11 -> 5.0896433e+08 | J11: =G11+I11 -> 7.2938839e+08
B12: =B11+0.01 -> 1.02 | C12: Licenciamiento SOS | D12: Un | E12: 88 | G12: =E12*F12 -> 0 | I12: =E12*H12 -> 0 | J12: =G12+I12 -> 0
B13: =B12+0.01 -> 1.03 | C13: Estructura metálica poste de 6m, Gabinete IP65 | D13: Un | E13: 88 | F13: 8904763.9 | G13: =E13*F13 -> 7.8361922e+08 | H13: 7776312.5 | I13: =E13*H13 -> 6.843155e+08 | J13: =G13+I13 -> 1.4679347e+09
B14: =B13+0.01 -> 1.04 | C14: Corona antiescalatoria | D14: Un | E14: 88 | F14: 737969.81 | G14: =E14*F14 -> 64941343 | H14: 225338.4 | I14: =E14*H14 -> 19829779 | J14: =G14+I14 -> 84771123
B15: =B14+0.01 -> 1.05 | C15: Cinturón(es) antivandálico(s) con candado(s) | D15: Un | E15: 176 | F15: 1191045.6 | G15: =E15*F15 -> 2.0962403e+08 | H15: 258200.78 | I15: =E15*H15 -> 45443337 | J15: =G15+I15 -> 2.5506736e+08
B16: =B15+0.01 -> 1.06 | C16: Señalización postes SOS, según manual de señalización vigente más (No.SOS x 2, Instrucciones de uso y rotulo en Braille) | D16: Un | E16: 88 | F16: 319476.85 | G16: =E16*F16 -> 28113963 | H16: 688534 | I16: =E16*H16 -> 60590992 | J16: =G16+I16 -> 88704955
B17: =B16+0.01 -> 1.07 | C17: Cintas retrorreflectivas de color blanco 2x | D17: Un | E17: 88 | G17: =E17*F17 -> 0 | I17: =E17*H17 -> 0 | J17: =G17+I17 -> 0
B18: =B17+0.01 -> 1.08 | C18: Paneles solares, indicar capacidad * | D18: Un | E18: 88 | F18: 12770505 | G18: =E18*F18 -> 1.1238045e+09 | H18: 273849.28 | I18: =E18*H18 -> 24098736 | J18: =G18+I18 -> 1.1479032e+09
B19: =B18+0.01 -> 1.09 | C19: Soporte metálico para paneles solares | D19: Un | E19: 88 | G19: =E19*F19 -> 0 | I19: =E19*H19 -> 0 | J19: =G19+I19 -> 0
B20: =B19+0.01 -> 1.1 | C20: Baterías, indicar capacidad para autonomía de 72 horas | D20: Un | E20: 88 | G20: =E20*F20 -> 0 | I20: =E20*H20 -> 0 | J20: =G20+I20 -> 0
B21: =B20+0.01 -> 1.11 | C21: Controlador para panel solar | D21: Un | E21: 88 | G21: =E21*F21 -> 0 | I21: =E21*H21 -> 0 | J21: =G21+I21 -> 0
B22: =B21+0.01 -> 1.12 | C22: Gabinete IP 65, sin ingreso de agua, para baterías, tablero eléctrico protecciones eléctricas, (Termomagnéticas y sobretensión) Incluye switch de puerta abierta, con accesorios de fijación y montaje. | D22: Un | E22: 88 | F22: 5503707 | G22: =E22*F22 -> 484326216 | H22: 2798928.7 | I22: =E22*H22 -> 2.4630573e+08 | J22: =G22+I22 -> 7.3063194e+08
B23: =B22+0.01 -> 1.13 | C23: Sistema Puesta a Tierra SOS. (Incluye varilla(s), caja de inspección, Soldadura, tratamiento de suelo y medida) | D23: Un | E23: 88 | F23: 4486477.7 | G23: =E23*F23 -> 3.9481004e+08 | H23: 3914826.5 | I23: =E23*H23 -> 3.4450474e+08 | J23: =G23+I23 -> 7.3931477e+08
B24: =B23+0.01 -> 1.14 | C24: Cimentación Dado de 80x80x80 cm. Estos deben disponer de dos tubos de 3” para el ingreso del cableado y con un anclaje de 4 pernos de acero galvanizado a tierra de ¾" de diámetro, estos son usados para soporte y fijación de los postes SOS. ** | D24: Un | E24: 88 | G24: =E24*F24 -> 0 | H24: 3609587.7 | I24: =E24*H24 -> 3.1764372e+08 | J24: =G24+I24 -> 3.1764372e+08
B25: =B24+0.01 -> 1.15 | C25: Placa de concreto que rodea la cimentación del poste de 1,50 m x 1,70 m, con 20 cm de espesor reforzada. Apta, desde la calzada, para el acceso personas con capacidad reducida, incluye obras civiles para lograr el acceso (demolición, adecuaciones). ** | D25: Un | E25: 88 | G25: =E25*F25 -> 0 | I25: =E25*H25 -> 0 | J25: =G25+I25 -> 0
B26: =B25+0.01 -> 1.16 | C26: Barandas de protección, 3 barandas, de 1,3 m ancho x 1,2 m de alto | D26: Un | E26: 88 | F26: 1962182.7 | G26: =E26*F26 -> 1.7267207e+08 | H26: 360959.08 | I26: =E26*H26 -> 31764399 | J26: =G26+I26 -> 2.0443647e+08
B27: =B26+0.01 -> 1.17 | C27: Caja para empalme de 8 puertos | D27: Un | E27: 88 | F27: 275560 | G27: =E27*F27 -> 24249280 | H27: 180620 | I27: =E27*H27 -> 15894560 | J27: =G27+I27 -> 40143840
B28: =B27+0.01 -> 1.18 | C28: Patch Cord fibra óptica mono modo lc - lc | D28: Un | E28: 176 | F28: 31385 | G28: =E28*F28 -> 5523760 | H28: 31603.894 | I28: =E28*H28 -> 5562285.4 | J28: =G28+I28 -> 11086045
B29: =B28+0.01 -> 1.19 | C29: Caja de empalme tipo botella (mufla) para F.O de 48 hilos con cierre térmico para uso subterráneo. | D29: Un | E29: 88 | F29: 192904 | G29: =E29*F29 -> 16975552 | H29: 170263 | I29: =E29*H29 -> 14983144 | J29: =G29+I29 -> 31958696
B30: =B29+0.01 -> 1.2 | C30: Cajas para la Red Troncal, de paso o derivación, de 80X80X80, dimensiones internas | D30: Un | E30: 176 | F30: 962106 | G30: =E30*F30 -> 169330656 | H30: 817672.2 | I30: =E30*H30 -> 1.4391031e+08 | J30: =G30+I30 -> 3.1324096e+08
B31: =B30+0.01 -> 1.21 | C31: Caja de reserva para micro cable de Fibra Óptica | D31: Un | E31: 88 | F31: 455761 | G31: =E31*F31 -> 40106968 | H31: 97455 | I31: =E31*H31 -> 8576040 | J31: =G31+I31 -> 48683008
B32: =B31+0.01 -> 1.22 | C32: Pig Tail | D32: Un | E32: 352 | F32: 7418.4565 | G32: =E32*F32 -> 2611296.7 | H32: 2017.5034 | I32: =E32*H32 -> 710161.2 | J32: =G32+I32 -> 3321457.9
B33: =B32+0.01 -> 1.23 | C33: Cable de servicio de FO, 8 hilos y longitud promedio de 30 m, con características de calidad iguales o mejores a las del microducto de la troncal. | D33: Un | E33: 88 | F33: 149435 | G33: =E33*F33 -> 13150280 | H33: 138607.72 | I33: =E33*H33 -> 12197479 | J33: =G33+I33 -> 25347759
B34: =B35+0.01 -> 1.25 | C34: Canalización y ducto Conduit de 1 y 1/2", entre la troncal de FO y el ITS, en longitud promedio de 30 m | D34: Un | E34: 88 | F34: 263833 | G34: =E34*F34 -> 23217304 | H34: 2265263.4 | I34: =E34*H34 -> 1.9934318e+08 | J34: =G34+I34 -> 2.2256048e+08
B35: =B33+0.01 -> 1.24 | C35: Fusiones | D35: Un | E35: 1056 | F35: 7441 | G35: =E35*F35 -> 7857696 | H35: 45514 | I35: =E35*H35 -> 48062784 | J35: =G35+I35 -> 55920480
B36: =B34+0.01 -> 1.26 | C36: Pequeño material de montaje | D36: Gbl | E36: 88 | F36: 2977793.9 | G36: =E36*F36 -> 2.6204586e+08 | I36: =E36*H36 -> 0 | J36: =G36+I36 -> 2.6204586e+08
B37: =B36+0.01 -> 1.27 | C37: Capacitación | D37: Gbl | E37: 1 | F37: 9000000 | G37: =E37*F37 -> 9000000 | I37: =E37*H37 -> 0 | J37: =G37+I37 -> 9000000
B38: =B37+0.01 -> 1.28 | C38: Retiro y disposición adecuada de las estructuras metálicas y/o de concreto de los antiguos postes SOS existentes y disposición en sitios apropiados y con certificación en ZODME. | D38: Un | E38: 15 | G38: =E38*F38 -> 0 | H38: 4500000 | I38: =E38*H38 -> 67500000 | J38: =G38+I38 -> 67500000
H40: TOTAL COSTOS DIRECTOS | J40: =SUM(J11:J37) -> 6.7891053e+09
F41: ADMINISTRACION (A) | I41: 0.22 | J41: =J40*I41 -> 1.4936032e+09
F42: IMPREVISTOS (I) | I42: 0.04 | J42: =J40*I42 -> 2.7156421e+08
F43: UTILIDAD (U) | I43: 0.04 | J43: =J40*I43 -> 2.7156421e+08
F44: SUBTOTAL COSTOS DIRECTOS + AIU
F45: IVA SOBRE LA UTILIDAD 19% | I45: 0.19 | J45: =J43*I45 -> 51597200
...

Sheet ESTACIÓN METEOROLOGICA
B2: PROYECTO TRONCAL MAGDALENA 1
B3: TABLA DE CANTIDADES | D3: PRESUPUESTO WUXY
B4: UNIDADES FUNCIONALES TOTAL 0 - 13
B6: ítem | C6: ITS | D6: Unidad | E6: Cantidad | F6: SUMINISTRO | H6: INSTALACIÓN PUESTA EN FUNCIONAMIENTO Y PRUEBAS | J6: COSTO TOTAL
B7: 2 | C7: ESTACIÓN METEOROLÓGICA | F7: Costo unitario | G7: Total suministro | H7: Costo unitario | I7: Total Instalación | J7: TOTAL
E8: TOTAL | F8: Col $ | G8: Col $ | H8: Col $ | I8: Col $ | J8: Col $
B9: =B7+0.01 -> 2.01 | C9: Estación Meteorológica integrada | D9: Un | E9: 4 | F9: =43966191*1.058 -> 46516230 | G9: =E9*F9 -> 1.8606492e+08 | H9: 1804793.3 | I9: =E9*H9 -> 7219173.3 | J9: =G9+I9 -> 1.9328409e+08
B10: =B9+0.01 -> 2.02 | C10: Sensor de visibilidad | D10: Un | E10: 4 | F10: =41305021*1.058 -> 43700712 | G10: =E10*F10 -> 1.7480285e+08 | I10: =E10*H10 -> 0 | J10: =G10+I10 -> 1.7480285e+08
B11: =B10+0.01 -> 2.03 | C11: Sensor de evapotranspiración potencial | D11: Un | E11: 4 | F11: =590000*2 -> 1180000 | G11: =E11*F11 -> 4720000 | H11: 450000 | I11: =E11*H11 -> 1800000 | J11: =G11+I11 -> 6520000
B12: =B11+0.01 -> 2.04 | C12: Paneles solares, indicar capacidad, no se requiere, se hará uso de la energía AC | D12: Un | E12: 0 | G12: =E12*F12 -> 0 | I12: =E12*H12 -> 0 | J12: =G12+I12 -> 0
B13: =B12+0.01 -> 2.05 | C13: Soporte metálico para paneles solares, no se requiere, se hará uso de la energía AC | D13: Un | E13: 0 | G13: =E13*F13 -> 0 | I13: =E13*H13 -> 0 | J13: =G13+I13 -> 0
B14: =B13+0.01 -> 2.06 | C14: Baterías, indicar capacidad para autonomía de 48 horas, no se requiere, se hará uso de la energía AC | D14: Un | E14: 0 | G14: =E14*F14 -> 0 | I14: =E14*H14 -> 0 | J14: =G14+I14 -> 0
B15: =B14+0.01 -> 2.07 | C15: Controlador para panel solar, no se requiere, se hará uso de la energía AC | D15: Un | E15: 0 | G15: =E15*F15 -> 0 | I15: =E15*H15 -> 0 | J15: =G15+I15 -> 0
B16: =B15+0.01 -> 2.08 | C16: Gabinete de control, protección IP65 sin ingreso de agua, el tamaño se ajustará dependiendo de los equipos a instalar y demás condiciones técnicas, con tablero eléctrico, protecciones eléctricas (Termomagnéticas y sobretensión). Incluye switch de puerta abierta, con accesorios de fijación y montaje. | D16: Un | E16: 4 | F16: =2747578*1.058 -> 2906937.5 | G16: =E16*F16 -> 11627750 | H16: 866300.96 | I16: =E16*H16 -> 3465203.8 | J16: =G16+I16 -> 15092954
B17: =B16+0.01 -> 2.09 | C17: Coraza liquid tight 3/4" | D17: Un | E17: 4 | F17: 150000 | G17: =E17*F17 -> 600000 | I17: =E17*H17 -> 0 | J17: =G17+I17 -> 600000
B18: =B17+0.01 -> 2.1 | C18: Conector Recto coraza liquid tight 3/4" acero galvanizado | D18: Un | E18: 4 | F18: 30500 | G18: =E18*F18 -> 122000 | I18: =E18*H18 -> 0 | J18: =G18+I18 -> 122000
B19: =B18+0.01 -> 2.11 | C19: Suministro e instalación Cable UTP CAT 6 certificado incluye ponchado y accesorios | D19: Un | E19: 4 | F19: =5632*1.058 -> 5958.656 | G19: =E19*F19 -> 23834.624 | H19: 4476.26 | I19: =E19*H19 -> 17905.04 | J19: =G19+I19 -> 41739.664
B20: =B19+0.01 -> 2.12 | C20: Poste octogonal de 6 metros en acero galvanizado para estación meteorológica. | D20: Un | E20: 4 | F20: =4998187*1.058 -> 5288081.8 | G20: =E20*F20 -> 21152327 | H20: 2487278.3 | I20: =E20*H20 -> 9949113.3 | J20: =G20+I20 -> 31101441
B21: =B20+0.01 -> 2.13 | C21: Cimentación para poste de la estación meteorológica. | D21: Un | E21: 4 | G21: =E21*F21 -> 0 | I21: =E21*H21 -> 0 | J21: =G21+I21 -> 0
B22: =B21+0.01 -> 2.14 | C22: Corona antiesclatoria | D22: Un | E22: 4 | G22: =E22*F22 -> 0 | I22: =E22*H22 -> 0 | J22: =G22+I22 -> 0
B23: =B22+0.01 -> 2.15 | C23: Canalización 80 m. | D23: Un | E23: 4 | G23: =E23*F23 -> 0 | I23: =E23*H23 -> 0 | J23: =G23+I23 -> 0
B24: =B23+0.01 -> 2.16 | C24: Cableado de energía y ducto 3/4", 90m aprox. | D24: Un | E24: 4 | G24: =E24*F24 -> 0 | I24: =E24*H24 -> 0 | J24: =G24+I24 -> 0
B25: =B24+0.01 -> 2.17 | C25: Cableado UTP Cat 6 y ducto 3/4", 90m aprox. | D25: Un | E25: 4 | G25: =E25*F25 -> 0 | I25: =E25*H25 -> 0 | J25: =G25+I25 -> 0
B26: =B25+0.01 -> 2.18 | C26: Puesta a tierra (Incluye varilla(s), caja de inspección, Soldadura, tratamiento de suelo y medida). | D26: Un | E26: 4 | G26: =E26*F26 -> 0 | I26: =E26*H26 -> 0 | J26: =G26+I26 -> 0
B27: =B26+0.01 -> 2.19 | C27: Encerramiento con malla eslabonada de 2,5 x 2,5 m y concertina. | D27: Un | E27: 4 | G27: =E27*F27 -> 0 | I27: =E27*H27 -> 0 | J27: =G27+I27 -> 0
B28: =B27+0.01 -> 2.2 | C28: Caja para empalme de 8 puertos. | D28: Un | E28: 4 | G28: =E28*F28 -> 0 | I28: =E28*H28 -> 0 | J28: =G28+I28 -> 0
B29: =B28+0.01 -> 2.21 | C29: Patch Cord fibra óptica mono modo lc - lc | D29: Un | E29: 8 | F29: 31385 | G29: =E29*F29 -> 251080 | H29: 31603.894 | I29: =E29*H29 -> 252831.15 | J29: =G29+I29 -> 503911.15
B30: =B29+0.01 -> 2.22 | C30: 'Caja de empalme tipo botella (mufla) para F.O de 48 hilos con cierre térmico para uso subterráneo. | D30: Un | E30: 4 | F30: 192904 | G30: =E30*F30 -> 771616 | H30: =153879+16384 -> 170263 | I30: =E30*H30 -> 681052 | J30: =G30+I30 -> 1452668
B31: =B29+0.01 -> 2.22 | C31: Cajas para la Red Troncal, de paso o derivación, de 80X80X80. | D31: Un | E31: 8 | F31: 962106 | G31: =E31*F31 -> 7696848 | H31: 817672.2 | I31: =E31*H31 -> 6541377.6 | J31: =G31+I31 -> 14238226
B32: =B31+0.01 -> 2.23 | C32: Caja de reserva para micro cable de Fibra Óptica. | D32: Un | E32: 4 | F32: 455761 | G32: =E32*F32 -> 1823044 | H32: 97455 | I32: =E32*H32 -> 389820 | J32: =G32+I32 -> 2212864
B33: =B32+0.01 -> 2.24 | C33: Pig Tail. | D33: Un | E33: 18 | F33: 7418.4565 | G33: =E33*F33 -> 133532.22 | H33: 2017.5034 | I33: =E33*H33 -> 36315.061 | J33: =G33+I33 -> 169847.28
B34: =B33+0.01 -> 2.25 | C34: Cable de servicio de FO, 8 hilos y longitud promedio de 80 m, con características de calidad iguales o mejores a las del microducto de la troncal. | D34: Un | E34: 4 | F34: 149435 | G34: =E34*F34 -> 597740 | H34: 138607.72 | I34: =E34*H34 -> 554430.87 | J34: =G34+I34 -> 1152170.9
B35: =B36+0.01 -> 2.27 | C35: Canalización y ducto Conduit de 1 y 1/2", entre la troncal de FO y el ITS, en longitud promedio de 80 m. | D35: Un | E35: 4 | F35: 263833 | G35: =E35*F35 -> 1055332 | H35: 2265263.4 | I35: =E35*H35 -> 9061053.5 | J35: =G35+I35 -> 10116386
B36: =B34+0.01 -> 2.26 | C36: Fusiones. | D36: Un | E36: 48 | F36: 7441 | G36: =E36*F36 -> 357168 | H36: 45514 | I36: =E36*H36 -> 2184672 | J36: =G36+I36 -> 2541840
B37: =B35+0.01 -> 2.28 | C37: Material de montaje + el cableado de energía y datos entre la estación meteorológica y el Switch en la edificación correspondiente. | D37: Gbl | E37: 4 | F37: =2814550*1.058*2 -> 5955587.8 | G37: =E37*F37 -> 23822351 | I37: =E37*H37 -> 0 | J37: =G37+I37 -> 23822351
B38: =B37+0.01 -> 2.29 | C38: Capacitación | D38: Gbl | E38: 1 | F38: 9000000 | G38: =E38*F38 -> 9000000 | I38: =E38*H38 -> 0 | J38: =G38+I38 -> 9000000
H40: TOTAL COSTOS DIRECTOS | J40: =SUM(J9:J38) -> 4.8677534e+08
F41: ADMINISTRACION (A) | I41: 0.22 | J41: =J40*I41 -> 1.0709057e+08
F42: IMPREVISTOS (I) | I42: 0.04 | J42: =J40*I42 -> 19471014
F43: UTILIDAD (U) | I43: 0.04 | J43: =J40*I43 -> 19471014
...

Sheet PMV
B2: PROYECTO TRONCAL MAGDALENA 1
B3: TABLA DE CANTIDADES | D3: PRESUPUESTO WUXY
B4: UNIDADES FUNCIONALES TOTAL 0 - 13
B6: ítem | C6: ITS | D6: Unidad | E6: Cantidad | F6: SUMINISTRO | H6: INSTALACIÓN PUESTA EN FUNCIONAMIENTO Y PRUEBAS | J6: COSTO TOTAL
B7: 3 | C7: PANEL DE MENSAJERÍA VARIABLE | F7: Costo unitario | G7: Total suministro | H7: Costo unitario | I7: Total Instalación | J7: TOTAL
E8: TOTAL | F8: Col $ | G8: Col $ | H8: Col $ | I8: Col $ | J8: Col $
B9: =B7+0.01 -> 3.01 | C9: Panel de Señalización Variable con 1 área grafica de 64x64 pixeles y 3 líneas con 12 caracteres cada una. | D9: Un | E9: 28 | F9: 1.506441e+08 | G9: =E9*F9 -> 4.2180348e+09 | H9: 6607129.1 | I9: =E9*H9 -> 1.8499962e+08 | J9: =G9+I9 -> 4.4030344e+09
B10: =B9+0.01 -> 3.02 | C10: Estructura metálica tipo pórtico visitable, según las normas técnicas de seguridad aplicables en Colombia. | D10: Un | E10: 0 | F10: 85404206 | G10: =E10*F10 -> 0 | H10: 16903672 | I10: =E10*H10 -> 0 | J10: =G10+I10 -> 0
B11: =B10+0.01 -> 3.03 | C11: Cimentación ( incluye estudio de suelos y diseño de cimentación para panel tipo pórtico) | D11: Un | E11: 0 | F11: 1265020 | G11: =E11*F11 -> 0 | H11: 32378602 | I11: =E11*H11 -> 0 | J11: =G11+I11 -> 0
B12: =B11+0.01 -> 3.04 | C12: Estructura metálica tipo Banderola | D12: Un | E12: 28 | F12: 50935519 | G12: =E12*F12 -> 1.4261945e+09 | H12: 6575759.8 | I12: =E12*H12 -> 1.8412128e+08 | J12: =G12+I12 -> 1.6103158e+09
B13: =B12+0.01 -> 3.05 | C13: Cimentación ( incluye estudio de suelos y diseño de cimentación para panel tipo banderola) | D13: Un | E13: 28 | F13: 1265021 | G13: =E13*F13 -> 35420587 | H13: 14097854 | I13: =E13*H13 -> 3.9473993e+08 | J13: =G13+I13 -> 4.3016051e+08
B14: =B13+0.01 -> 3.06 | C14: Gabinete de control, protección IP65 sin ingreso de agua, el tamaño se ajustará dependiendo de los equipos a instalar y demás condiciones técnicas, con tablero eléctrico, protecciones eléctricas (Termomagnéticas y sobretensión). Incluye switch de puerta abierta, con accesorios de fijación y montaje | D14: Un | E14: 28 | F14: 5360021 | G14: =E14*F14 -> 150080588 | H14: 1439183.3 | I14: =E14*H14 -> 40297134 | J14: =G14+I14 -> 1.9037772e+08
B15: =B14+0.01 -> 3.07 | C15: UPS con autonomía de 15 minutos para el panel 1G3L. Se utiliza como una medida de protección adicional para el panel. | D15: Un | E15: 28 | F15: 12349335 | G15: =E15*F15 -> 345781380 | H15: 5437338.8 | I15: =E15*H15 -> 1.5224549e+08 | J15: =G15+I15 -> 4.9802687e+08
B16: =B15+0.01 -> 3.08 | C16: Cableado de energía eléctrica | D16: Un | E16: 28 | F16: 5429786 | G16: =E16*F16 -> 152034008 | H16: 1713552.3 | I16: =E16*H16 -> 47979465 | J16: =G16+I16 -> 2.0001347e+08
B17: =B16+0.01 -> 3.09 | C17: Puesta a tierra (Incluye varilla(s), caja de inspección, Soldadura, tratamiento de suelo y medida) | D17: Un | E17: 28 | F17: 4832728 | G17: =E17*F17 -> 135316384 | H17: 2682921.9 | I17: =E17*H17 -> 75121814 | J17: =G17+I17 -> 2.104382e+08
B18: =B17+0.01 -> 3.1 | C18: Pararrayos (incluye materiales) | D18: Un | E18: 28 | F18: 4656287 | G18: =E18*F18 -> 130376036 | H18: 1075857.3 | I18: =E18*H18 -> 30124003 | J18: =G18+I18 -> 1.6050004e+08
B19: =B18+0.01 -> 3.11 | C19: Materiales menores de montaje de Paneles y UPS | D19: Un | E19: 28 | F19: 1265020 | G19: =E19*F19 -> 35420560 | H19: 527984.07 | I19: =E19*H19 -> 14783554 | J19: =G19+I19 -> 50204114
B20: =B19+0.01 -> 3.12 | C20: Acometida AC, incluyendo el contador y la certificación RETIE, dimensionada con una reserva en potencia del 20% para el Switch, una cámara etc. | D20: Un | E20: 28 | F20: 54408062 | G20: =E20*F20 -> 1523425736 | H20: 44766860 | I20: =E20*H20 -> 1.2534721e+09 | J20: =G20+I20 -> 2.7768978e+09
B21: =B20+0.01 -> 3.13 | C21: Caja para empalme de 8 puertos | D21: Un | E21: 28 | F21: 275560 | G21: =E21*F21 -> 7715680 | H21: 180620 | I21: =E21*H21 -> 5057360 | J21: =G21+I21 -> 12773040
... B27: =B26+0.01 -> 3.19 | C27: Cable de servicio de FO, 8 hilos y longitud promedio de 30 m, con características de calidad iguales o mejores a las del microducto de la troncal. | D27: Un | E27: 28 | F27: 149435 | G27: =E27*F27 -> 4184180 | H27: 138607.72 | I27: =E27*H27 -> 3881016.1 | J27: =G27+I27 -> 8065196.1
B28: =B29+0.01 -> 3.21 | C28: Canalización y ducto Conduit de 1 y 1/2", entre la troncal de FO y el ITS, en longitud promedio de 30 m | D28: Un | E28: 28 | F28: 263833 | G28: =E28*F28 -> 7387324 | H28: 2265263.4 | I28: =E28*H28 -> 63427375 | J28: =G28+I28 -> 70814699
B29: =B27+0.01 -> 3.2 | C29: Fusiones | D29: Un | E29: 336 | F29: 7441 | G29: =E29*F29 -> 2500176 | H29: 45514 | I29: =E29*H29 -> 15292704 | J29: =G29+I29 -> 17792880
B30: =B28+0.01 -> 3.22 | C30: Señalización de los postes y estructuras según Manual de Señalización vigente. | D30: Gbl | E30: 28 | F30: 319476.85 | G30: =E30*F30 -> 8945351.9 | H30: 688534 | I30: =E30*H30 -> 19278952 | J30: =G30+I30 -> 28224304
B31: =B30+0.01 -> 3.23 | C31: Material de montaje | D31: Gbl | E31: 28 | F31: 2977793.9 | G31: =E31*F31 -> 83378229 | I31: =E31*H31 -> 0 | J31: =G31+I31 -> 83378229
B32: =B31+0.01 -> 3.24 | C32: Capacitación | D32: Gbl | E32: 1 | F32: 9000000 | G32: =E32*F32 -> 9000000 | I32: =E32*H32 -> 0 | J32: =G32+I32 -> 9000000
B33: =B32+0.01 -> 3.25 | C33: Retiro y disposición adecuada de las estructuras metálicas y/o de concreto del PMV existente, dispuestos en sitios apropiados y con certificación en ZODME. | D33: Un | E33: 1 | G33: =E33*F33 -> 0 | H33: 10350000 | I33: =E33*H33 -> 10350000 | J33: =G33+I33 -> 10350000
H35: TOTAL COSTOS DIRECTOS | J35: =SUM(J9:J33) -> 1.0900278e+10
F36: ADMINISTRACION (A) | I36: 0.22 | J36: =J35*I36 -> 2.3980611e+09
F37: IMPREVISTOS (I) | I37: 0.04 | J37: =J35*I37 -> 4.3601111e+08
F38: UTILIDAD (U) | I38: 0.04 | J38: =J35*I38 -> 4.3601111e+08
F39: SUBTOTAL COSTOS DIRECTOS + AIU
F40: IVA SOBRE LA UTILIDAD 19% | I40: 0.19 | J40: =J38*I40 -> 82842112
H42: TOTAL COSTO DIRECTO+AIU + IVA | J42: =SUM(J35:J40) -> 1.4253203e+10

Sheet GALIBO
B2: PROYECTO TRONCAL MAGDALENA 1
B3: TABLA DE CANTIDADES | D3: PRESUPUESTO WUXY
B4: UNIDADES FUNCIONALES TOTAL 0 - 13
B6: ítem | C6: ITS | D6: Unidad | E6: Cantidad | F6: SUMINISTRO | H6: INSTALACIÓN PUESTA EN FUNCIONAMIENTO Y PRUEBAS | J6: COSTO TOTAL
B7: 4 | C7: SISTEMA DE CONTROL DE ALTURA | F7: Costo unitario | G7: Total suministro | H7: Costo unitario | I7: Total Instalación | J7: TOTAL
E8: TOTAL | F8: Col $ | G8: Col $ | H8: Col $ | I8: Col $ | J8: Col $
B9: =B7+0.01 -> 4.01 | C9: Fotocélulas Emisor Receptor Doble 2X | D9: Un | E9: 8 | F9: 8786361 | G9: =E9*F9 -> 70290888 | I9: =E9*H9 -> 0 | J9: =G9+I9 -> 70290888
B10: =B9+0.01 -> 4.02 | C10: Gabinete de control, protección IP65 sin ingreso de agua, el tamaño se ajustará dependiendo de los equipos a instalar y demás condiciones técnicas, con equipo de control, PLC, tablero eléctrico, protecciones eléctricas, (Termomagnéticas y sobretensión) incluye switch de puerta abierta, con accesorios de fijación y montaje | D10: Un | E10: 8 | F10: 24952697 | G10: =E10*F10 -> 1.9962158e+08 | H10: 866300.96 | I10: =E10*H10 -> 6930407.7 | J10: =G10+I10 -> 2.0655199e+08
B11: =B10+0.01 -> 4.03 | C11: Suministro e instalación de juego de espiras inductivas en pavimento incluye corte sobre pavimento, herramientas, materiales, equipo, mano de obra, restauración de cualquier estructura afectada como corona, cunetas entre otras, limpieza, remoción de escombros hasta el sitio de desechos, todo según especificaciones técnicas. | D11: Un | E11: 8 | F11: 5257300 | G11: =E11*F11 -> 42058400 | H11: 610077.94 | I11: =E11*H11 -> 4880623.6 | J11: =G11+I11 -> 46939024
B12: =B11+0.01 -> 4.04 | C12: Poste octogonal de 6 metros en acero galvanizado para gálibo electrónico 2X | D12: Un | E12: 8 | F12: 5288081.8 | G12: =E12*F12 -> 42304655 | H12: 2487278.3 | I12: =E12*H12 -> 19898227 | J12: =G12+I12 -> 62202881
B13: =B12+0.01 -> 4.05 | C13: Cimentación para las columnas del gálibo electrónico 2X | D13: Un | E13: 8 | G13: =E13*F13 -> 0 | H13: 3609587.7 | I13: =E13*H13 -> 28876701 | J13: =G13+I13 -> 28876701
B14: =B13+0.01 -> 4.06 | C14: Juego de cámara de evidencias más cámara de identificación de placas, Incluye el software | D14: Un | E14: 8 | F14: 35374700 | G14: =E14*F14 -> 282997600 | I14: =E14*H14 -> 0 | J14: =G14+I14 -> 282997600
B15: =B14+0.01 -> 4.07 | C15: Poste octogonal de 6 metros en acero galvanizado para cámara de evidencias más cámara de identificación de placas | D15: Un | E15: 8 | F15: 5288081.8 | G15: =E15*F15 -> 42304655 | H15: 2487278.3 | I15: =E15*H15 -> 19898227 | J15: =G15+I15 -> 62202881
B16: =B15+0.01 -> 4.08 | C16: Cimentación para el poste de cámara de evidencias más cámara de identificación de placas | D16: Un | E16: 8 | G16: =E16*F16 -> 0 | H16: 3609587.7 | I16: =E16*H16 -> 28876701 | J16: =G16+I16 -> 28876701
B17: =B16+0.01 -> 4.09 | C17: PMV señal exceso de altura (Señal oculta) | D17: Un | E17: 8 | F17: 42967431 | G17: =E17*F17 -> 3.4373945e+08 | H17: 1443835.3 | I17: =E17*H17 -> 11550682 | J17: =G17+I17 -> 3.5529013e+08
B18: =B17+0.01 -> 4.1 | C18: Estructura metálica tipo horquilla para PMV (Señal oculta) | D18: Un | E18: 8 | F18: 5451449.7 | G18: =E18*F18 -> 43611598 | H18: 1815945.6 | I18: =E18*H18 -> 14527565 | J18: =G18+I18 -> 58139162
B19: =B18+0.01 -> 4.11 | C19: Cimentación PMV (Señal oculta) | D19: Un | E19: 8 | G19: =E19*F19 -> 0 | H19: 3609587.7 | I19: =E19*H19 -> 28876701 | J19: =G19+I19 -> 28876701
B20: =B19+0.01 -> 4.12 | C20: Estructura metálica tipo pórtico - Galibo mecánico, con cadenas | D20: Un | E20: 8 | F20: 40904016 | G20: =E20*F20 -> 3.2723213e+08 | H20: 6169262.5 | I20: =E20*H20 -> 49354100 | J20: =G20+I20 -> 3.7658623e+08
B21: =B20+0.01 -> 4.13 | C21: Cimentación estructura tipo pórtico, incluye análisis de suelos 2X | D21: Un | E21: 8 | F21: 1265020 | G21: =E21*F21 -> 10120160 | H21: 32378602 | I21: =E21*H21 -> 2.5902882e+08 | J21: =G21+I21 -> 2.6914898e+08
B22: =B21+0.01 -> 4.14 | C22: Canalización entre señal oculta y gálibo electrónico aprox 80m | D22: Un | E22: 8 | F22: 1675618.1 | G22: =E22*F22 -> 13404945 | H22: 8250499.4 | I22: =E22*H22 -> 66003995 | J22: =G22+I22 -> 79408940
B23: =B22+0.01 -> 4.15 | C23: Cableado de energía y ducto de 1 y 1/2" hasta la señal oculta 90m aprox | D23: Un | E23: 8 | F23: 1177395.3 | G23: =E23*F23 -> 9419162.4 | H23: 454842.72 | I23: =E23*H23 -> 3638741.8 | J23: =G23+I23 -> 13057904
B24: =B23+0.01 -> 4.16 | C24: Cableado UTP Cat 6 y ducto de 1 y 1/2" hasta la señal oculta 90m aprox | D24: Un | E24: 8 | F24: 536279.04 | G24: =E24*F24 -> 4290232.3 | H24: 4476.26 | I24: =E24*H24 -> 35810.08 | J24: =G24+I24 -> 4326042.4
B25: =B24+0.01 -> 4.17 | C25: Paneles solares, indicar capacidad * | D25: Un | E25: 8 | F25: 29114139 | G25: =E25*F25 -> 232913112 | H25: 4388231.8 | I25: =E25*H25 -> 35105854 | J25: =G25+I25 -> 2.6801897e+08
B26: =B25+0.01 -> 4.18 | C26: Soporte metálico para paneles solares | D26: Un | E26: 8 | G26: =E26*F26 -> 0 | I26: =E26*H26 -> 0 | J26: =G26+I26 -> 0
B27: =B26+0.01 -> 4.19 | C27: Baterías, indicar capacidad para autonomía de 48 horas | D27: Un | E27: 8 | G27: =E27*F27 -> 0 | I27: =E27*H27 -> 0 | J27: =G27+I27 -> 0
B28: =B27+0.01 -> 4.2 | C28: Controlador para panel solar | D28: Un | E28: 8 | G28: =E28*F28 -> 0 | I28: =E28*H28 -> 0 | J28: =G28+I28 -> 0
B29: =B28+0.01 -> 4.21 | C29: Puesta a tierra (Incluye varilla(s), caja de inspección, Soldadura, tratamiento de suelo y medida) | D29: Un | E29: 8 | F29: 4832728 | G29: =E29*F29 -> 38661824 | H29: 2682921.9 | I29: =E29*H29 -> 21463375 | J29: =G29+I29 -> 60125199
B30: =B29+0.01 -> 4.22 | C30: Señalización de los postes y estructuras según Manual de Señalización vigente. | D30: Gbl | E30: 8 | F30: 638953.71 | G30: =E30*F30 -> 5111629.7 | H30: 1377068 | I30: =E30*H30 -> 11016544 | J30: =G30+I30 -> 16128174
B31: =B30+0.01 -> 4.23 | C31: Caja para empalme de 8 puertos | D31: Un | E31: 8 | F31: 275560 | G31: =E31*F31 -> 2204480 | H31: 180620 | I31: =E31*H31 -> 1444960 | J31: =G31+I31 -> 3649440
B32: =B31+0.01 -> 4.24 | C32: Patch Cord fibra óptica mono modo lc - lc | D32: Un | E32: 16 | F32: 31385 | G32: =E32*F32 -> 502160 | H32: 31603.894 | I32: =E32*H32 -> 505662.31 | J32: =G32+I32 -> 1007822.3
B33: =B32+0.01 -> 4.25 | C33: Caja de empalme tipo botella (mufla) para F.O de 48 hilos con cierre térmico para uso subterráneo. | D33: Un | E33: 8 | F33: 192904 | G33: =E33*F33 -> 1543232 | H33: 170263 | I33: =E33*H33 -> 1362104 | J33: =G33+I33 -> 2905336
B34: =B33+0.01 -> 4.26 | C34: Cajas para la Red Troncal, de paso o derivación, de 80X80X80, dimensiones internas | D34: Un | E34: 16 | F34: 962106 | G34: =E34*F34 -> 15393696 | H34: 817672.2 | I34: =E34*H34 -> 13082755 | J34: =G34+I34 -> 28476451
B35: =B34+0.01 -> 4.27 | C35: Caja de reserva para micro cable de Fibra Óptica | D35: Un | E35: 8 | F35: 455761 | G35: =E35*F35 -> 3646088 | H35: 97455 | I35: =E35*H35 -> 779640 | J35: =G35+I35 -> 4425728
B36: =B35+0.01 -> 4.28 | C36: Pig Tail | D36: Un | E36: 32 | F36: 7418.4565 | G36: =E36*F36 -> 237390.61 | H36: 2017.5034 | I36: =E36*H36 -> 64560.109 | J36: =G36+I36 -> 301950.72
B37: =B36+0.01 -> 4.29 | C37: Cable de servicio de FO, 8 hilos y longitud promedio de 30 m, con características de calidad iguales o mejores a las del microducto de la troncal. | D37: Un | E37: 8 | F37: 149435 | G37: =E37*F37 -> 1195480 | H37: 138607.72 | I37: =E37*H37 -> 1108861.7 | J37: =G37+I37 -> 2304341.7
B38: =B39+0.01 -> 4.31 | C38: Canalización y ducto Conduit de 1 y 1/2", entre la troncal de FO y el ITS, en longitud promedio de 30 m | D38: Un | E38: 8 | F38: 263833 | G38: =E38*F38 -> 2110664 | H38: 2265263.4 | I38: =E38*H38 -> 18122107 | J38: =G38+I38 -> 20232771
B39: =B37+0.01 -> 4.3 | C39: Fusiones | D39: Un | E39: 96 | F39: 7441 | G39: =E39*F39 -> 714336 | H39: 45514 | I39: =E39*H39 -> 4369344 | J39: =G39+I39 -> 5083680
B40: =B38+0.01 -> 4.32 | C40: Material de montaje | D40: Gbl | E40: 8 | F40: 2977793.9 | G40: =E40*F40 -> 23822351 | I40: =E40*H40 -> 0 | J40: =G40+I40 -> 23822351
B41: =B40+0.01 -> 4.33 | C41: Capacitación | D41: Gbl | E41: 1 | F41: 9000000 | G41: =E41*F41 -> 9000000 | I41: =E41*H41 -> 0 | J41: =G41+I41 -> 9000000
H43: TOTAL COSTOS DIRECTOS | J43: =SUM(J9:J41) -> 2.419255e+09
...

Sheet ETD
B2: PROYECTO TRONCAL MAGDALENA 1
B3: TABLA DE CANTIDADES | D3: PRESUPUESTO WUXY
B4: UNIDADES FUNCIONALES TOTAL 0 - 13
B6: ítem | C6: ITS | D6: Unidad | E6: Cantidad | F6: SUMINISTRO | H6: INSTALACIÓN PUESTA EN FUNCIONAMIENTO Y PRUEBAS | J6: COSTO TOTAL
B7: 5 | C7: ESTACIÓN TOMA DE DATOS | F7: Costo unitario | G7: Total suministro | H7: Costo unitario | I7: Total Instalación | J7: TOTAL
E8: TOTAL | F8: Col $ | G8: Col $ | H8: Col $ | I8: Col $ | J8: Col $
B9: =B7+0.01 -> 5.01 | C9: Controlador Estación de Toma de Datos ETD | D9: Un | E9: 12 | F9: 53600002 | G9: =E9*F9 -> 6.4320003e+08 | H9: 3619694.2 | I9: =E9*H9 -> 43436331 | J9: =G9+I9 -> 6.8663636e+08
B10: =B9+0.01 -> 5.02 | C10: Gabinete de control, protección IP65 sin ingreso de agua, el tamaño se ajustará dependiendo de los equipos a instalar y demás condiciones técnicas, con tablero eléctrico, protecciones eléctricas, (Termomagnéticas y sobretensión) incluye switch de puerta abierta, con accesorios de fijación y montaje | D10: Un | E10: 12 | F10: 6934396.5 | G10: =E10*F10 -> 83212758 | H10: 866300.96 | I10: =E10*H10 -> 10395612 | J10: =G10+I10 -> 93608370
B11: =B10+0.01 -> 5.03 | C11: Cámara para analítica de video, con su soporte | D11: Un | E11: 12 | F11: 35374700 | G11: =E11*F11 -> 424496400 | I11: =E11*H11 -> 0 | J11: =G11+I11 -> 424496400
B12: =B11+0.01 -> 5.04 | C12: Paneles solares, indicar capacidad * | D12: Un | E12: 12 | F12: 9704713 | G12: =E12*F12 -> 116456556 | H12: 1462743.9 | I12: =E12*H12 -> 17552927 | J12: =G12+I12 -> 1.3400948e+08
B13: =B12+0.01 -> 5.05 | C13: Soporte metálico para paneles solares | D13: Un | E13: 12 | G13: =E13*F13 -> 0 | I13: =E13*H13 -> 0 | J13: =G13+I13 -> 0
B14: =B13+0.01 -> 5.06 | C14: Baterías, indicar capacidad para autonomía de 48 horas | D14: Un | E14: 12 | G14: =E14*F14 -> 0 | I14: =E14*H14 -> 0 | J14: =G14+I14 -> 0
B15: =B14+0.01 -> 5.07 | C15: Controlador para panel solar | D15: Un | E15: 12 | G15: =E15*F15 -> 0 | I15: =E15*H15 -> 0 | J15: =G15+I15 -> 0
B16: =B15+0.01 -> 5.08 | C16: Poste en concreto 14 m | D16: Un | E16: 12 | F16: 2999598 | G16: =E16*F16 -> 35995176 | H16: 680994.05 | I16: =E16*H16 -> 8171928.6 | J16: =G16+I16 -> 44167105
B17: =B16+0.01 -> 5.09 | C17: Corona antiescalatoria | D17: Un | E17: 12 | F17: 737969.81 | G17: =E17*F17 -> 8855637.7 | H17: 225338.4 | I17: =E17*H17 -> 2704060.8 | J17: =G17+I17 -> 11559699
B18: =B17+0.01 -> 5.1 | C18: Cableado Energía | D18: Un | E18: 12 | F18: 812392.94 | G18: =E18*F18 -> 9748715.2 | H18: 328466.1 | I18: =E18*H18 -> 3941593.2 | J18: =G18+I18 -> 13690308
B19: =B18+0.01 -> 5.11 | C19: Cableado Control | D19: Un | E19: 12 | F19: 389948.61 | G19: =E19*F19 -> 4679383.3 | H19: 310191.81 | I19: =E19*H19 -> 3722301.7 | J19: =G19+I19 -> 8401685
B20: =B19+0.01 -> 5.12 | C20: Cable UTP Cat 6 Datos | D20: Un | E20: 12 | F20: 1624785.9 | G20: =E20*F20 -> 19497430 | H20: 1634674.4 | I20: =E20*H20 -> 19616093 | J20: =G20+I20 -> 39113524
B21: =B20+0.01 -> 5.13 | C21: Puesta a tierra (Incluye varilla(s), caja de inspección, Soldadura, tratamiento de suelo y medida) | D21: Un | E21: 12 | F21: 4486477.7 | G21: =E21*F21 -> 53837733 | H21: 3914826.5 | I21: =E21*H21 -> 46977918 | J21: =G21+I21 -> 1.0081565e+08
B22: =B21+0.01 -> 5.14 | C22: Señalización del poste según Manual de Señalización vigente | D22: Gbl | E22: 12 | F22: 319476.85 | G22: =E22*F22 -> 3833722.2 | H22: 688534 | I22: =E22*H22 -> 8262408 | J22: =G22+I22 -> 12096130
B23: =B22+0.01 -> 5.15 | C23: Caja para empalme de 8 puertos | D23: Un | E23: 12 | F23: 275560 | G23: =E23*F23 -> 3306720 | H23: 180620 | I23: =E23*H23 -> 2167440 | J23: =G23+I23 -> 5474160
B24: =B23+0.01 -> 5.16 | C24: Patch Cord fibra óptica mono modo lc - lc | D24: Un | E24: 12 | F24: 31385 | G24: =E24*F24 -> 376620 | H24: 31603.894 | I24: =E24*H24 -> 379246.73 | J24: =G24+I24 -> 755866.73
B25: =B24+0.01 -> 5.17 | C25: Caja de empalme tipo botella (mufla) para F.O de 48 hilos con cierre térmico para uso subterráneo. | D25: Un | E25: 12 | F25: 192904 | G25: =E25*F25 -> 2314848 | H25: 170263 | I25: =E25*H25 -> 2043156 | J25: =G25+I25 -> 4358004
B26: =B25+0.01 -> 5.18 | C26: Cajas para la Red Troncal, de paso o derivación, de 80X80X80, dimensiones internas | D26: Un | E26: 24 | F26: 962106 | G26: =E26*F26 -> 23090544 | H26: 817672.2 | I26: =E26*H26 -> 19624133 | J26: =G26+I26 -> 42714677
B27: =B26+0.01 -> 5.19 | C27: Caja de reserva para micro cable de Fibra Óptica | D27: Un | E27: 12 | F27: 455761 | G27: =E27*F27 -> 5469132 | H27: 97455 | I27: =E27*H27 -> 1169460 | J27: =G27+I27 -> 6638592
... B29: =B28+0.01 -> 5.21 | C29: Cable de servicio de FO, 8 hilos y longitud promedio de 40 m, con características de calidad iguales o mejores a las del microducto de la troncal. | D29: Un | E29: 12 | F29: 149435 | G29: =E29*F29 -> 1793220 | H29: 138607.72 | I29: =E29*H29 -> 1663292.6 | J29: =G29+I29 -> 3456512.6
B30: =B31+0.01 -> 5.23 | C30: Canalización y ducto Conduit de 1 y 1/2", entre la troncal de FO y el ITS, en longitud promedio de 30 m | D30: Un | E30: 12 | F30: 263833 | G30: =E30*F30 -> 3165996 | H30: 2265263.4 | I30: =E30*H30 -> 27183161 | J30: =G30+I30 -> 30349157
B31: =B29+0.01 -> 5.22 | C31: Fusiones | D31: Un | E31: 144 | F31: 7441 | G31: =E31*F31 -> 1071504 | H31: 45514 | I31: =E31*H31 -> 6554016 | J31: =G31+I31 -> 7625520
B32: =B30+0.01 -> 5.24 | C32: Pequeño material de montaje | D32: Gbl | E32: 12 | F32: 2977793.9 | G32: =E32*F32 -> 35733527 | I32: =E32*H32 -> 0 | J32: =G32+I32 -> 35733527
B33: =B32+0.01 -> 5.25 | C33: Capacitación | D33: Gbl | E33: 1 | F33: 9000000 | G33: =E33*F33 -> 9000000 | I33: =E33*H33 -> 0 | J33: =G33+I33 -> 9000000
H35: TOTAL COSTOS DIRECTOS | J35: =SUM(J9:J33) -> 1.7151537e+09
F36: ADMINISTRACION (A) | I36: 0.22 | J36: =J35*I36 -> 3.773338e+08
F37: IMPREVISTOS (I) | I37: 0.04 | J37: =J35*I37 -> 68606146
F38: UTILIDAD (U) | I38: 0.04 | J38: =J35*I38 -> 68606146
F39: SUBTOTAL COSTOS DIRECTOS + AIU
F40: IVA SOBRE LA UTILIDAD 19% | I40: 0.19 | J40: =J38*I40 -> 13035168
H42: TOTAL COSTO DIRECTO+AIU + IVA | J42: =SUM(J35:J40) -> 2.2427349e+09
B44: * | C44: El presupuesto de la solución solar incluye la totalidad de la solución

Sheet CCTV
B2: PROYECTO TRONCAL MAGDALENA 1
B3: TABLA DE CANTIDADES | D3: PRESUPUESTO WUXY
B4: UNIDADES FUNCIONALES TOTAL 0 - 13
B6: ítem | C6: ITS | D6: Unidad | E6: Cantidad | F6: SUMINISTRO | H6: INSTALACIÓN PUESTA EN FUNCIONAMIENTO Y PRUEBAS | J6: COSTO TOTAL
B7: 6 | C7: SISTEMA DE CCTV | F7: Costo unitario | G7: Total suministro | H7: Costo unitario | I7: Total Instalación | J7: TOTAL
E8: TOTAL | F8: Col $ | G8: Col $ | H8: Col $ | I8: Col $ | J8: Col $
B9: =B7+0.01 -> 6.01 | C9: Cámara PTZ Vía | D9: Un | E9: 30 | F9: 5251452 | G9: =E9*F9 -> 157543560 | H9: 2682748.3 | I9: =E9*H9 -> 80482450 | J9: =G9+I9 -> 2.3802601e+08
B10: =B9+0.01 -> 6.02 | C10: Soporte poste cámara | D10: Un | E10: 30 | F10: 175410 | G10: =E10*F10 -> 5262300 | H10: 203136.99 | I10: =E10*H10 -> 6094109.8 | J10: =G10+I10 -> 11356410
B11: =B10+0.01 -> 6.03 | C11: Brazo extensión cámara | D11: Un | E11: 30 | F11: 549178 | G11: =E11*F11 -> 16475340 | H11: 219306.23 | I11: =E11*H11 -> 6579187 | J11: =G11+I11 -> 23054527
B12: =B11+0.01 -> 6.04 | C12: Postes concreto CCTV de 14 m | D12: Un | E12: 30 | F12: 2999598 | G12: =E12*F12 -> 89987940 | H12: 680994.05 | I12: =E12*H12 -> 20429822 | J12: =G12+I12 -> 1.1041776e+08
B13: =B12+0.01 -> 6.05 | C13: Corona antiescalatoria | D13: Un | E13: 30 | F13: 737969.81 | G13: =E13*F13 -> 22139094 | H13: 225338.4 | I13: =E13*H13 -> 6760152 | J13: =G13+I13 -> 28899246
B14: =B13+0.01 -> 6.06 | C14: Paneles solares, indicar capacidad * | D14: Un | E14: 30 | F14: 9704713 | G14: =E14*F14 -> 291141390 | H14: 1462743.9 | I14: =E14*H14 -> 43882318 | J14: =G14+I14 -> 3.3502371e+08
B15: =B14+0.01 -> 6.07 | C15: Soporte metálico para paneles solares | D15: Un | E15: 30 | G15: =E15*F15 -> 0 | I15: =E15*H15 -> 0 | J15: =G15+I15 -> 0
B16: =B15+0.01 -> 6.08 | C16: Baterías, indicar capacidad para autonomía de 48 horas | D16: Un | E16: 30 | G16: =E16*F16 -> 0 | I16: =E16*H16 -> 0 | J16: =G16+I16 -> 0
B17: =B16+0.01 -> 6.09 | C17: Controlador para panel solar | D17: Un | E17: 30 | G17: =E17*F17 -> 0 | I17: =E17*H17 -> 0 | J17: =G17+I17 -> 0
B18: =B17+0.01 -> 6.1 | C18: Gabinete de control, protección IP65 sin ingreso de agua, el tamaño se ajustará dependiendo de los equipos a instalar y demás condiciones técnicas, con tablero eléctrico, protecciones eléctricas, (Termomagnéticas y sobretensión) incluye switch de puerta abierta, con accesorios de fijación y montaje | D18: Un | E18: 30 | F18: 9121928 | G18: =E18*F18 -> 273657840 | H18: 2798928.7 | I18: =E18*H18 -> 83967861 | J18: =G18+I18 -> 3.576257e+08
